<?xml version="1.0"?>
<robot xmlns:xacro="http://www.ros.org/wiki/xacro">

    <xacro:macro name="rim" params="side xyz rpy color">
        <link name="${side}_rim_link">
            <visual>
                <origin xyz="0 0 0" rpy="0 0 0"/>
                <geometry>
                    <mesh filename="package://omni_description/meshes/wheel/rim.stl" scale="${scale} ${scale} ${scale}" />
                </geometry>
                <material name="${color}"/>
            </visual>
            <collision>
                <origin xyz="0 0 0" rpy="0 0 0"/>
                <geometry>
                    <mesh filename="package://omni_description/meshes/wheel/rim.stl" scale="${scale} ${scale} ${scale}" />
                </geometry>
            </collision>
            <inertial>
                <origin xyz="0 0 0" rpy="0 0 0"/>
                <mass value="${0.00835758 * scale}"/>
                <inertia ixx="${6.63684e-07 * scale * scale}" ixy="0" ixz="0"
                         iyy="${6.63684e-07 * scale * scale}" iyz="0"
                         izz="${9.40333e-07 * scale * scale}"/>
            </inertial>
        </link>
        <joint name="base_${side}_rim_joint" type="continuous">
            <parent link="base_link"/>
            <child link="${side}_rim_link"/>
            <origin xyz="${xyz}" rpy="${rpy}"/>
            <axis xyz="0 0 1"/>
        </joint>
    </xacro:macro>

    <xacro:rim side="left"	xyz="${-0.03464101615*scale}	${0.02*scale}	${0*scale}"	rpy="${90*pi/180} 0 ${60*pi/180}"	color="red" />
    <xacro:rim side="right"	xyz="${0.03464101615*scale}		${0.02*scale}	${0*scale}"	rpy="${90*pi/180} 0 ${-60*pi/180}"	color="green" />
    <xacro:rim side="back"	xyz="${0*scale}					${-0.04*scale}	${0*scale}"	rpy="${90*pi/180} 0 ${-180*pi/180}"	color="blue" />

</robot>